<?xml version="1.0"?>
<robot xmlns:xacro="http://www.ros.org/wiki/xacro">
<xacro:include filename="inertial_macros.xacro" />


    <material name="white">
        <color rgba="1 1 1 1"/>
    </material>

    <material name="orange">
        <color rgba="1 0.3 0.1 1"/>
    </material>

    <material name="blue">
        <color rgba="0.2 0.2 1 1"/>
    </material>

    <material name="black">
        <color rgba="0 0 0 1"/>
    </material>

    <!--BASE LINK-->
    <link name="base_link">
    
    </link>

    <!--CHASSIS LINK-->

    <joint name="chassis_joint" type="fixed">
        <parent link="base_link"/>
        <child link="chassis"/>
        <origin xyz="-0.1 0 0"/>
        <axis xyz="0 0 1"/>
    </joint>

    <link name="chassis">
        <visual>
        
            <origin xyz="0.41 0 0.155" rpy="0 0 0"/>
            <geometry>
                <box size="0.82 0.64 0.31"/>
            </geometry>
            <material name="white"/>

        </visual>

        <collision>
    
            <origin xyz="0.41 0 0.155" rpy="0 0 0"/>
            <geometry>
                <box size="0.82 0.64 0.31"/>
            </geometry>

        </collision>

        <xacro:inertial_box mass="0.5" x="0.3" y="0.3" z="0.15">
            <origin xyz="0.41 0 0.155" rpy="0 0 0"/>
        </xacro:inertial_box>

    </link>  


    <!--LEFT WHEEL-->
    
<joint name="left_wheel_joint" type="continuous">
    <parent link="base_link"/>
    <child link="left_wheel"/>
    <origin xyz="0 0.32 0" rpy="-${pi/2} 0 0"/>
    <axis xyz="0 0 1"/>
</joint>

<link name="left_wheel">
    <visual>

        <geometry>
            <cylinder length="0.04" radius="0.1" />
        </geometry>
        <material name="blue"/>

    </visual>

    <collision>

        <geometry>
            <cylinder length="0.04" radius="0.1" />
        </geometry>
        
    </collision>

     <xacro:inertial_cylinder mass="0.1" length="0.04" radius="0.1">
        <origin xyz="0 0 0" rpy="0 0 0"/>
    </xacro:inertial_cylinder>

</link>

   <!--RIGHT  WHEEL-->
    
<joint name="right_wheel_joint" type="continuous">
    <parent link="base_link"/>
    <child link="right_wheel"/>
    <origin xyz="0 -0.32 0" rpy="${pi/2} 0 0"/>
    <axis xyz="0 0 -1"/>
</joint>

<link name="right_wheel">
    <visual>

        <geometry>
            <cylinder length="0.04" radius="0.1" />
        </geometry>
        <material name="blue"/>

    </visual>

    <collision>

        <geometry>
            <cylinder length="0.04" radius="0.1" />
        </geometry>

    </collision>

    <xacro:inertial_cylinder mass="0.1" length="0.04" radius="0.1">
        <origin xyz="0 0 0" rpy="0 0 0"/>
    </xacro:inertial_cylinder>

</link>

    <!--STEERING-->

    <!--LEFT-->

<joint name="steering_wheel_joint" type="revolute">
    <parent link="chassis"/>
    <child link="Steering_wheel_left"/>
    <origin xyz="0.66 0.32 0" rpy="-${pi/2} 0 0"/>
    <limit lower="-0.389" upper="0.389" effort="2" velocity="1.0"/>
    <axis xyz="0 1 0"/>
</joint>

<link name="Steering_wheel_left">
    <visual>

        <geometry>
            <cylinder radius="0.1" length="0.04" />
        </geometry>
        <material name="black"/>

    </visual>

    <collision>

        <geometry>
            <cylinder radius="0.1" length="0.04" />
        </geometry>

    </collision>

    <xacro:inertial_cylinder mass="0.1" length="0.04" radius="0.1">
        <origin xyz="0 0 0" rpy="0 0 0"/>
    </xacro:inertial_cylinder>

</link>
<gazebo reference="Steering_wheel_left">
    <mu1 value="0.1"/>
    <mu2 value="0.1"/>
</gazebo>

    <!--RIGHT-->

<joint name="steering_wheel_joint_r" type="revolute">
    <parent link="chassis"/>
    <child link="Steering_wheel_right"/>
    <origin xyz="0.66 -0.32 0" rpy="-${pi/2} 0 0"/>
    <limit lower="-0.389" upper="0.389" effort="2" velocity="1.0"/>
    <axis xyz="0 1 0"/>
</joint>

<link name="Steering_wheel_right">

    <visual>
        <geometry>
            <cylinder radius="0.1" length="0.04" />
        </geometry>
        <material name="black"/>
    </visual>

    <collision>
        <geometry>
            <cylinder radius="0.1" length="0.04" />
        </geometry>
        <material name="black"/>
    </collision>

    <xacro:inertial_cylinder mass="0.1" length="0.04" radius="0.1">
        <origin xyz="0 0 0" rpy="0 0 0"/>
    </xacro:inertial_cylinder>
</link>   
<gazebo reference="Steering_wheel_right">
    <mu1 value="0.1"/>
    <mu2 value="0.1"/>
</gazebo>

 </robot>